Workbook

Sheet Players
A1: Player_ID | B1: Player_Name | C1: Status | D1: TGL Team
A2: 1 | B2: Art Hernandez | C2: Member | D2: The Money Team
A3: 2 | B3: Adrianna Moore | C3: Member | D3: None
A4: 3 | B4: Andy Pendleton | C4: Member | D4: White Rice
A5: 4 | B5: Brock Hansen | C5: Member | D5: None
A6: 5 | B6: Bryan Cappelli | C6: Member | D6: Just the Tips
A7: 6 | B7: Carlos Bouloy | C7: Member | D7: The Money Team
A8: 7 | B8: Chris Chang | C8: Member | D8: Just the Tips
A9: 8 | B9: Colin Chang | C9: Member | D9: White Rice
A10: 9 | B10: Colin Harrison | C10: Member | D10: Just the Tips
A11: 10 | B11: Danny Lopez | C11: Member | D11: 19th Hole Cartel
A12: 11 | B12: Danny Marin | C12: Member | D12: The Money Team
A13: 12 | B13: Darrick Sogabe | C13: Member | D13: The Money Team
... A47: 46 | B47: Tyler Nichols | C47: Guest | D47: None

Sheet Tournament_Info
A1: Tournament_ID | B1: Tournament_Name | C1: Date | D1: Course | E1: TGL Event
A2: 2026_01 | B2: CCRB | C2: 46053 | D2: CCRB | E2: No
A3: 2026_02 | B3: Cross Creek | C3: 46075 | D3: Cross Creek GC | E3: Yes
A4: 2026_03 | B4: Sycuan | C4: 46110 | D4: Sycuan Resort | E4: Yes
A5: 2026_04 | B5: The Vineyard at Escondido | C5: 46131 | D5: The Vineyard at Escondido | E5: Yes
A6: 2026_05 | B6: The Links at Lakehouse | C6: 46159 | D6: The Links at Lakehouse | E6: Yes
A7: 2026_06 | B7: Native Oaks | C7: 46201 | D7: Native Oaks | E7: Yes
A8: 2026_07 | B8: Coronado Golf Club | C8: Sunday, July 12, 2026 | D8: Coronado Golf Club | E8: Yes
A9: 2026_08 | B9: CCRB | C9: Sunday, August 2, 2026 | D9: CCRB | E9: Yes
A10: 2026_09 | B10: San Vicente | C10: Sunday, August 30, 2026 | D10: San Vicente | E10: Yes
A11: 2026_10 | B11: Arrowood Golf Club | C11: Sunday, September 20, 2026 | D11: Arrowood Golf Club | E11: Yes
A12: 2026_11 | B12: Golf Club of California | C12: 46320 | D12: Golf Club of California | E12: Yes
A13: 2026_12 | B13: Twin Oaks Golf Club | C13: 46341 | D13: Twin Oaks Golf Club | E13: Yes

Sheet Tournament_Results
A1: Tournament ID | B1: Player ID | C1: Player | D1: Flight | E1: Handicap | F1: Gross | G1: Net | H1: Front 9 | I1: Back 9 | J1: Putts | K1: TGL Player | L1: TGL Points
A2: 2026_01 | B2: =_xlfn.XLOOKUP(C2,Players!B:B,Players!A:A) -> 36 | C2: Taylor Yates | D2: A | E2: 9 | F2: 79 | G2: 70 | H2: 36 | I2: 43 | J2: TBD | K2: N/A
A3: 2026_01 | B3: =_xlfn.XLOOKUP(C3,Players!B:B,Players!A:A) -> 34 | C3: Tai Ho | D3: A | E3: 15 | F3: 85 | G3: 70 | H3: 42 | I3: 43 | J3: TBD | K3: N/A
A4: 2026_01 | B4: =_xlfn.XLOOKUP(C4,Players!B:B,Players!A:A) -> 12 | C4: Darrick Sogabe | D4: A | E4: 19 | F4: 92 | G4: 73 | H4: 46 | I4: 46 | J4: TBD | K4: N/A | N4: Player, Flight, Handicap, Gross Score, Net Score, Front 9 Grose Score, Back 9 Gross Score and total putts.
A5: 2026_01 | B5: =_xlfn.XLOOKUP(C5,Players!B:B,Players!A:A) -> 35 | C5: Tam Tran | D5: A | E5: 20 | F5: 93 | G5: 73 | H5: 46 | I5: 47 | J5: TBD | K5: N/A
A6: 2026_01 | B6: =_xlfn.XLOOKUP(C6,Players!B:B,Players!A:A) -> 8 | C6: Colin Chang | D6: A | E6: 18 | F6: 94 | G6: 76 | H6: 45 | I6: 49 | J6: TBD | K6: N/A
A7: 2026_01 | B7: =_xlfn.XLOOKUP(C7,Players!B:B,Players!A:A) -> 37 | C7: Tom Shea | D7: A | E7: 5 | F7: 84 | G7: 79 | H7: 39 | I7: 45 | J7: TBD | K7: N/A
A8: 2026_01 | B8: =_xlfn.XLOOKUP(C8,Players!B:B,Players!A:A) -> 16 | C8: Jorge Rayo | D8: A | E8: 16 | F8: 97 | G8: 81 | H8: 48 | I8: 49 | J8: TBD | K8: N/A
A9: 2026_01 | B9: =_xlfn.XLOOKUP(C9,Players!B:B,Players!A:A) -> 17 | C9: JP Hill | D9: A | E9: 13 | F9: 96 | G9: 83 | H9: 44 | I9: 52 | J9: TBD | K9: N/A
A10: 2026_01 | B10: =_xlfn.XLOOKUP(C10,Players!B:B,Players!A:A) -> 6 | C10: Carlos Bouloy | D10: A | E10: 19 | F10: 102 | G10: 83 | H10: 51 | I10: 51 | J10: TBD | K10: N/A
A11: 2026_01 | B11: =_xlfn.XLOOKUP(C11,Players!B:B,Players!A:A) -> 15 | C11: John Nothdurft | D11: A | E11: 10 | F11: 95 | G11: 85 | H11: 47 | I11: 48 | J11: TBD | K11: N/A
A12: 2026_01 | B12: =_xlfn.XLOOKUP(C12,Players!B:B,Players!A:A) -> 27 | C12: Nick Harris | D12: A | E12: 17 | F12: 103 | G12: 86 | H12: 51 | I12: 52 | J12: TBD | K12: N/A
A13: 2026_01 | B13: =_xlfn.XLOOKUP(C13,Players!B:B,Players!A:A) -> 20 | C13: Kevin Vargas | D13: A | E13: 8 | F13: 95 | G13: 87 | H13: 47 | I13: 48 | J13: TBD | K13: N/A
A14: 2026_01 | B14: =_xlfn.XLOOKUP(C14,Players!B:B,Players!A:A) -> 7 | C14: Chris Chang | D14: A | E14: 13 | F14: 100 | G14: 87 | H14: 50 | I14: 50 | J14: TBD | K14: N/A
A15: 2026_01 | B15: =_xlfn.XLOOKUP(C15,Players!B:B,Players!A:A) -> 45 | C15: Devin Lerner | D15: A | E15: 17 | F15: 104 | G15: 87 | H15: 53 | I15: 51 | J15: TBD | K15: N/A
A16: 2026_01 | B16: =_xlfn.XLOOKUP(C16,Players!B:B,Players!A:A) -> 3 | C16: Andy Pendleton | D16: A | E16: 7 | F16: 95 | G16: 88 | H16: 51 | I16: 44 | J16: TBD | K16: N/A
... A37: 2026_01 | B37: =_xlfn.XLOOKUP(C37,Players!B:B,Players!A:A) -> 22 | C37: Mark Horgan | D37: B | E37: 24 | F37: 118 | G37: 94 | H37: 59 | I37: 59 | J37: TBD | K37: N/A
A38: 2026_02 | B38: =_xlfn.XLOOKUP(C38,Players!B:B,Players!A:A) -> 20 | C38: Kevin Vargas | D38: A | E38: 9 | F38: 83 | G38: 74 | H38: 39 | I38: 44 | J38: TBD | K38: Yes | L38: 12
A39: 2026_02 | B39: =_xlfn.XLOOKUP(C39,Players!B:B,Players!A:A) -> 4 | C39: Brock Hansen | D39: A | E39: 20 | F39: 98 | G39: 78 | H39: 47 | I39: 51 | J39: TBD | K39: No
A40: 2026_02 | B40: =_xlfn.XLOOKUP(C40,Players!B:B,Players!A:A) -> 3 | C40: Andy Pendleton | D40: A | E40: 8 | F40: 89 | G40: 81 | H40: 43 | I40: 46 | J40: TBD | K40: No
A41: 2026_02 | B41: =_xlfn.XLOOKUP(C41,Players!B:B,Players!A:A) -> 6 | C41: Carlos Bouloy | D41: A | E41: 21 | F41: 102 | G41: 81 | H41: 52 | I41: 50 | J41: TBD | K41: No
A42: 2026_02 | B42: =_xlfn.XLOOKUP(C42,Players!B:B,Players!A:A) -> 36 | C42: Taylor Yates | D42: A | E42: 9 | F42: 92 | G42: 83 | H42: 48 | I42: 44 | J42: TBD | K42: Yes | L42: 8
A43: 2026_02 | B43: =_xlfn.XLOOKUP(C43,Players!B:B,Players!A:A) -> 29 | C43: Paul Toledo | D43: A | E43: 13 | F43: 96 | G43: 83 | H43: 48 | I43: 48 | J43: TBD | K43: No
A44: 2026_02 | B44: =_xlfn.XLOOKUP(C44,Players!B:B,Players!A:A) -> 35 | C44: Tam Tran | D44: A | E44: 21 | F44: 105 | G44: 84 | H44: 53 | I44: 52 | J44: TBD | K44: No
A45: 2026_02 | B45: =_xlfn.XLOOKUP(C45,Players!B:B,Players!A:A) -> 32 | C45: Spencer Higgins | D45: A | E45: 11 | F45: 100 | G45: 89 | H45: 53 | I45: 47 | J45: TBD | K45: No
A46: 2026_02 | B46: =_xlfn.XLOOKUP(C46,Players!B:B,Players!A:A) -> 34 | C46: Tai Ho | D46: A | E46: 14 | F46: 104 | G46: 90 | H46: 59 | I46: 45 | J46: TBD | K46: Yes | L46: 4
A47: 2026_02 | B47: =_xlfn.XLOOKUP(C47,Players!B:B,Players!A:A) -> 12 | C47: Darrick Sogabe | D47: A | E47: 20 | F47: 111 | G47: 91 | H47: 56 | I47: 55 | J47: TBD | K47: No
A48: 2026_02 | B48: =_xlfn.XLOOKUP(C48,Players!B:B,Players!A:A) -> 15 | C48: John Nothdurft | D48: A | E48: 12 | F48: 107 | G48: 95 | H48: 50 | I48: 57 | J48: TBD | K48: No
A49: 2026_02 | B49: =_xlfn.XLOOKUP(C49,Players!B:B,Players!A:A) -> 5 | C49: Bryan Cappelli | D49: A | E49: 13 | F49: 117 | G49: 104 | H49: 61 | I49: 56 | J49: TBD | K49: No
A50: 2026_02 | B50: =_xlfn.XLOOKUP(C50,Players!B:B,Players!A:A) -> 28 | C50: Paul Hsieh | D50: B | E50: 34 | F50: 106 | G50: 72 | H50: 50 | I50: 56 | J50: TBD | K50: No
A51: 2026_02 | B51: =_xlfn.XLOOKUP(C51,Players!B:B,Players!A:A) -> 26 | C51: Mikel Hodges | D51: B | E51: 20 | F51: 93 | G51: 73 | H51: 49 | I51: 44 | J51: TBD | K51: Yes | L51: 11
A52: 2026_02 | B52: =_xlfn.XLOOKUP(C52,Players!B:B,Players!A:A) -> 9 | C52: Colin Harrison | D52: B | E52: 19 | F52: 93 | G52: 74 | H52: 45 | I52: 48 | J52: TBD | K52: Yes | L52: 10
A53: 2026_02 | B53: =_xlfn.XLOOKUP(C53,Players!B:B,Players!A:A) -> 18 | C53: Juan Ramirez | D53: B | E53: 36 | F53: 113 | G53: 77 | H53: 57 | I53: 56 | J53: TBD | K53: No
A54: 2026_02 | B54: =_xlfn.XLOOKUP(C54,Players!B:B,Players!A:A) -> 19 | C54: Kevin Taylor | D54: B | E54: 24 | F54: 102 | G54: 78 | H54: 54 | I54: 48 | J54: TBD | K54: Yes | L54: 8
A55: 2026_02 | B55: =_xlfn.XLOOKUP(C55,Players!B:B,Players!A:A) -> 10 | C55: Danny Lopez | D55: B | E55: 20 | F55: 98 | G55: 78 | H55: 48 | I55: 50 | J55: TBD | K55: No
A56: 2026_02 | B56: =_xlfn.XLOOKUP(C56,Players!B:B,Players!A:A) -> 1 | C56: Art Hernandez | D56: B | E56: 20 | F56: 103 | G56: 83 | H56: 55 | I56: 48 | J56: TBD | K56: Yes | L56: 5.5
A57: 2026_02 | B57: =_xlfn.XLOOKUP(C57,Players!B:B,Players!A:A) -> 24 | C57: Mike Paguyo | D57: B | E57: 24 | F57: 107 | G57: 83 | H57: 55 | I57: 52 | J57: TBD | K57: No
A58: 2026_02 | B58: =_xlfn.XLOOKUP(C58,Players!B:B,Players!A:A) -> 30 | C58: Ken Sogabe | D58: B | E58: 33 | F58: 121 | G58: 88 | H58: 63 | I58: 58 | J58: TBD | K58: No
A59: 2026_02 | B59: =_xlfn.XLOOKUP(C59,Players!B:B,Players!A:A) -> 22 | C59: Mark Horgan | D59: B | E59: 22 | F59: 115 | G59: 93 | H59: 57 | I59: 58 | J59: TBD | K59: No
A60: 2026_02 | B60: =_xlfn.XLOOKUP(C60,Players!B:B,Players!A:A) -> 23 | C60: Max O'Brien | D60: B | E60: 22 | F60: 121 | G60: 99 | H60: 61 | I60: 60 | J60: TBD | K60: Yes | L60: 2
...

Sheet Tournament_Acheivements
A1: Tournament ID | B1: Player ID | C1: Player | D1: Category | E1: Placement | F1: Amount
A2: 2026_05 | B2: =_xlfn.XLOOKUP(C2,Players!B:B,Players!A:A) -> 41 | C2: Mat Vigil | D2: Flight A - Overall | E2: 1 | F2: 70
A3: 2026_05 | B3: =_xlfn.XLOOKUP(C3,Players!B:B,Players!A:A) -> 13 | C3: David Wu | D3: Flight A - Overall | E3: 2 | F3: 35
A4: 2026_05 | B4: =_xlfn.XLOOKUP(C4,Players!B:B,Players!A:A) -> 35 | C4: Tam Tran | D4: Flight A - Overall | E4: 2 | F4: 35
A5: 2026_05 | B5: =_xlfn.XLOOKUP(C5,Players!B:B,Players!A:A) -> 14 | C5: Devan French | D5: Flight B - Overall | E5: 1 | F5: 65
A6: 2026_05 | B6: =_xlfn.XLOOKUP(C6,Players!B:B,Players!A:A) -> 10 | C6: Danny Lopez | D6: Flight B - Overall | E6: 2 | F6: 39
A7: 2026_05 | B7: =_xlfn.XLOOKUP(C7,Players!B:B,Players!A:A) -> 43 | C7: Jason Payton | D7: Flight B - Overall | E7: 3 | F7: 26
A8: 2026_05 | B8: =_xlfn.XLOOKUP(C8,Players!B:B,Players!A:A) -> 41 | C8: Mat Vigil | D8: Flight A - Front 9 | E8: 1 | F8: 21
A9: 2026_05 | B9: =_xlfn.XLOOKUP(C9,Players!B:B,Players!A:A) -> 13 | C9: David Wu | D9: Flight A - Front 9 | E9: 1 | F9: 21
A10: 2026_05 | B10: =_xlfn.XLOOKUP(C10,Players!B:B,Players!A:A) -> 14 | C10: Devan French | D10: Flight B - Front 9 | E10: 1 | F10: 26
A11: 2026_05 | B11: =_xlfn.XLOOKUP(C11,Players!B:B,Players!A:A) -> 9 | C11: Colin Harrison | D11: Flight B - Front 9 | E11: 2 | F11: 13
A12: 2026_05 | B12: =_xlfn.XLOOKUP(C12,Players!B:B,Players!A:A) -> 17 | C12: JP Hill | D12: Flight A - Back 9 | E12: 1 | F12: 28
A13: 2026_05 | B13: =_xlfn.XLOOKUP(C13,Players!B:B,Players!A:A) -> 15 | C13: John Nothdurft | D13: Flight A - Back 9 | E13: 2 | F13: 14
... A15: 2026_05 | B15: =_xlfn.XLOOKUP(C15,Players!B:B,Players!A:A) -> 1 | C15: Art Hernandez | D15: Flight B - Back 9 | E15: 1 | F15: 19.5
A16: 2026_05 | B16: =_xlfn.XLOOKUP(C16,Players!B:B,Players!A:A) -> 15 | C16: John Nothdurft | D16: Low Putts | E16: Winner | F16: 27
A17: 2026_05 | B17: =_xlfn.XLOOKUP(C17,Players!B:B,Players!A:A) -> 20 | C17: Kevin Vargas | D17: Flight A - Long Drive | E17: Winner | F17: 28
A18: 2026_05 | B18: =_xlfn.XLOOKUP(C18,Players!B:B,Players!A:A) -> 19 | C18: Kevin Taylor | D18: Flight B - Long Drive | E18: Winner | F18: 26
A19: 2026_05 | B19: =_xlfn.XLOOKUP(C19,Players!B:B,Players!A:A) -> 20 | C19: Kevin Vargas | D19: Closest to the Pin | E19: Winner | F19: 27
A20: 2026_05 | B20: =_xlfn.XLOOKUP(C20,Players!B:B,Players!A:A) -> 44 | C20: Med Baheta | D20: Closest to the Pin | E20: Winner | F20: 27
A21: 2026_05 | B21: =_xlfn.XLOOKUP(C21,Players!B:B,Players!A:A) -> 29 | C21: Paul Toledo | D21: Closest to the Pin | E21: Winner | F21: 27
A22: 2026_05 | B22: =_xlfn.XLOOKUP(C22,Players!B:B,Players!A:A) -> 25 | C22: Mike Pena | D22: Closest to the Pin | E22: Winner | F22: 27
A23: 2026_05 | B23: =_xlfn.XLOOKUP(C23,Players!B:B,Players!A:A) -> 1 | C23: Art Hernandez | D23: Closest to the Pin | E23: Winner | F23: 27
A24: 2026_04 | B24: =_xlfn.XLOOKUP(C24,Players!B:B,Players!A:A) -> 29 | C24: Paul Toledo | D24: Flight A - Overall | E24: 1 | F24: 90
A25: 2026_04 | B25: =_xlfn.XLOOKUP(C25,Players!B:B,Players!A:A) -> 40 | C25: Lucas Bouloy | D25: Flight A - Overall | E25: 2 | F25: 54
A26: 2026_04 | B26: =_xlfn.XLOOKUP(C26,Players!B:B,Players!A:A) -> 20 | C26: Kevin Vargas | D26: Flight A - Overall | E26: 3 | F26: 12
A27: 2026_04 | B27: =_xlfn.XLOOKUP(C27,Players!B:B,Players!A:A) -> 10 | C27: Danny Lopez | D27: Flight B - Overall | E27: 1 | F27: 72
A28: 2026_04 | B28: =_xlfn.XLOOKUP(C28,Players!B:B,Players!A:A) -> 19 | C28: Kevin Taylor | D28: Flight B - Overall | E28: 1 | F28: 72
A29: 2026_04 | B29: =_xlfn.XLOOKUP(C29,Players!B:B,Players!A:A) -> 18 | C29: Juan Ramirez | D29: Flight B - Overall | E29: 3 | F29: 36
A30: 2026_04 | B30: =_xlfn.XLOOKUP(C30,Players!B:B,Players!A:A) -> 29 | C30: Paul Toledo | D30: Flight A - Front 9 | E30: 1 | F30: 27
A31: 2026_04 | B31: =_xlfn.XLOOKUP(C31,Players!B:B,Players!A:A) -> 40 | C31: Lucas Bouloy | D31: Flight A - Front 9 | E31: 1 | F31: 27
A32: 2026_04 | B32: =_xlfn.XLOOKUP(C32,Players!B:B,Players!A:A) -> 19 | C32: Kevin Taylor | D32: Flight B - Front 9 | E32: 1 | F32: 36
A33: 2026_04 | B33: =_xlfn.XLOOKUP(C33,Players!B:B,Players!A:A) -> 1 | C33: Art Hernandez | D33: Flight B - Front 9 | E33: 2 | F33: 18
A34: 2026_04 | B34: =_xlfn.XLOOKUP(C34,Players!B:B,Players!A:A) -> 34 | C34: Tai Ho | D34: Flight A - Back 9 | E34: 1 | F34: 36
A35: 2026_04 | B35: =_xlfn.XLOOKUP(C35,Players!B:B,Players!A:A) -> 7 | C35: Chris Chang | D35: Flight A - Back 9 | E35: 2 | F35: 18
... A37: 2026_04 | B37: =_xlfn.XLOOKUP(C37,Players!B:B,Players!A:A) -> 18 | C37: Juan Ramirez | D37: Flight B - Back 9 | E37: 2 | F37: 9
A38: 2026_04 | B38: =_xlfn.XLOOKUP(C38,Players!B:B,Players!A:A) -> 3 | C38: Andy Pendleton | D38: Low Putts | E38: Winner | F38: 36
A39: 2026_04 | B39: =_xlfn.XLOOKUP(C39,Players!B:B,Players!A:A) -> 16 | C39: Jorge Rayo | D39: Flight A - Long Drive | E39: Winner | F39: 36
A40: 2026_04 | B40: =_xlfn.XLOOKUP(C40,Players!B:B,Players!A:A) -> 28 | C40: Paul Hsieh | D40: Flight B - Long Drive | E40: Winner | F40: 36
A41: 2026_04 | B41: =_xlfn.XLOOKUP(C41,Players!B:B,Players!A:A) -> 37 | C41: Tom Shea | D41: Closest to the Pin | E41: Winner | F41: 45
A42: 2026_04 | B42: =_xlfn.XLOOKUP(C42,Players!B:B,Players!A:A) -> 20 | C42: Kevin Vargas | D42: Closest to the Pin | E42: Winner | F42: 45
...

Sheet Tournament_Skins
A1: Tournament ID | B1: Player ID | C1: Player | D1: Category | E1: Total | F1: Amount
A2: 2026_05 | B2: =_xlfn.XLOOKUP(C2,Players!B:B,Players!A:A) -> 15 | C2: John Nothdurft | D2: Flight A - Skins | E2: 9 | F2: 126
A3: 2026_05 | B3: =_xlfn.XLOOKUP(C3,Players!B:B,Players!A:A) -> 13 | C3: David Wu | D3: Flight A - Skins | E3: 3 | F3: 42
A4: 2026_05 | B4: =_xlfn.XLOOKUP(C4,Players!B:B,Players!A:A) -> 20 | C4: Kevin Vargas | D4: Flight A - Skins | E4: 3 | F4: 42
A5: 2026_05 | B5: =_xlfn.XLOOKUP(C5,Players!B:B,Players!A:A) -> 44 | C5: Med Baheta | D5: Flight A - Skins | E5: 3 | F5: 42
A6: 2026_05 | B6: =_xlfn.XLOOKUP(C6,Players!B:B,Players!A:A) -> 14 | C6: Devan French | D6: Flight B - Skins | E6: 6 | F6: 78
A7: 2026_05 | B7: =_xlfn.XLOOKUP(C7,Players!B:B,Players!A:A) -> 10 | C7: Danny Lopez | D7: Flight B - Skins | E7: 3 | F7: 39
A8: 2026_05 | B8: =_xlfn.XLOOKUP(C8,Players!B:B,Players!A:A) -> 25 | C8: Mike Pena | D8: Flight B - Skins | E8: 3 | F8: 39
A9: 2026_05 | B9: =_xlfn.XLOOKUP(C9,Players!B:B,Players!A:A) -> 43 | C9: Jason Payton | D9: Flight B - Skins | E9: 2 | F9: 26
A10: 2026_05 | B10: =_xlfn.XLOOKUP(C10,Players!B:B,Players!A:A) -> 28 | C10: Paul Hsieh | D10: Flight B - Skins | E10: 2 | F10: 26
A11: 2026_05 | B11: =_xlfn.XLOOKUP(C11,Players!B:B,Players!A:A) -> 1 | C11: Art Hernandez | D11: Flight B - Skins | E11: 1 | F11: 13
A12: 2026_05 | B12: =_xlfn.XLOOKUP(C12,Players!B:B,Players!A:A) -> 9 | C12: Colin Harrison | D12: Flight B - Skins | E12: 1 | F12: 13
A13: 2026_04 | B13: =_xlfn.XLOOKUP(C13,Players!B:B,Players!A:A) -> 34 | C13: Tai Ho | D13: Flight A - Skins | E13: 2 | F13: 36
... A57: 2026_03 | B57: =_xlfn.XLOOKUP(C57,Players!B:B,Players!A:A) -> 28 | C57: Paul Hsieh | D57: Flight B - Skins | E57: 7 | F57: 98
